package examples.xxx

import kotlinx.coroutines.CoroutineExceptionHandler
import kotlinx.coroutines.GlobalScope
import kotlinx.coroutines.launch
import kotlinx.coroutines.runBlocking
import kotlin.coroutines.ContinuationInterceptor

fun main() = runBlocking {
    val handler = CoroutineExceptionHandler { _, exception ->
        println("Caught $exception")
    }
    val job = GlobalScope.launch(handler) {
        throw AssertionError()
    }
    job.join() // Caught java.lang.AssertionError
    ContinuationInterceptor
}